<?xml version="1.0"?>
<robot xmlns:xacro="http://www.ros.org/wiki/xacro" name="agri_robot">

  <!-- Include inertia macros -->
  <xacro:include filename="inertial_macros.xacro" />

  <!-- Materials -->
  <material name="white"><color rgba="1 1 1 1"/></material>
  <material name="green"><color rgba="0.2 0.6 0.2 1"/></material>
  <material name="blue"><color rgba="0.2 0.2 1 1"/></material>
  <material name="black"><color rgba="0 0 0 1"/></material>
  <material name="red"><color rgba="1 0 0 1"/></material>
  <material name="brown"><color rgba="0.55 0.27 0.07 1"/></material>

  <!-- BASE LINK -->
  <link name="base_link">
    
  </link>

  <!-- CHASSIS LINK -->
  <joint name="chassis_joint" type="fixed">
    <parent link="base_link"/>
    <child link="chassis"/>
    <origin xyz="0 0 0.35"/>
  </joint>

  <link name="chassis">
    <xacro:inertial_box mass="60.0" x="1.8" y="1.0" z="0.5"/>
    <visual>
      <origin xyz="0 0 0.35"/>
        <geometry><box size="1.8 1.0 0.5"/></geometry> 
      </origin>
      <material name="green"/>
    </visual>

    <collision>
      <origin xyz="0 0 0.35"/>
        <geometry><box size="1.8 1.0 0.5"/></geometry>
      </origin>
    </collision>

  </link>


  <!-- WHEELS -->
  <!-- Rear Left -->
  <joint name="rear_left_wheel_joint" type="continuous">
    <parent link="base_link"/>
    <child link="rear_left_wheel"/>
    <origin xyz="-0.6 0.45 0.35" rpy="-${pi/2} 0 0"/>
    <axis xyz="0 1 0"/>
  </joint>

  <link name="rear_left_wheel">
    <xacro:inertial_cylinder mass="6.0" radius="0.35" length="0.2"/>
    <visual>
      <geometry><cylinder radius="0.35" length="0.2"/></geometry>
      <material name="black"/>
    </visual>

    <collision>
      <geometry><cylinder radius="0.35" length="0.2"/></geometry>
    </collision>
  </link>
  

  <!-- Rear Right -->
  <joint name="rear_right_wheel_joint" type="continuous">
    <parent link="base_link"/>
    <child link="rear_right_wheel"/>
    <origin xyz="-0.6 -0.45 0.35" rpy="${pi/2} 0 0"/>
    <axis xyz="0 1 0"/>
  </joint>

  <link name="rear_right_wheel">
    <xacro:inertial_cylinder mass="6.0" radius="0.35" length="0.2"/>
    <visual>
      <geometry><cylinder radius="0.35" length="0.2"/></geometry>
      <material name="black"/>
    </visual>

    <collision>
      <geometry><cylinder radius="0.35" length="0.2"/></geometry>
    </collision>
  </link>
  

  <!-- Front Left -->
  <joint name="front_left_wheel_joint" type="continuous">
    <parent link="base_link"/>
    <child link="front_left_wheel"/>
    <origin xyz="0.6 0.45 0.35" rpy="-${pi/2} 0 0"/>
    <axis xyz="0 1 0"/>
  </joint>

  <link name="front_left_wheel">
    <xacro:inertial_cylinder mass="4.0" radius="0.35" length="0.2"/>
    <visual>
      <geometry><cylinder radius="0.35" length="0.2"/></geometry>
      <material name="black"/>
    </visual>
    <collision>
      <geometry><cylinder radius="0.35" length="0.2"/></geometry>
    </collision>
  </link>
  

  <!-- Front Right -->
  <joint name="front_right_wheel_joint" type="continuous">
    <parent link="base_link"/>
    <child link="front_right_wheel"/>
    <origin xyz="0.7 -0.45 0.35" rpy="${pi/2} 0 0"/>
    <axis xyz="0 1 0"/>
  </joint>

  <link name="front_right_wheel">
    <xacro:inertial_cylinder mass="4.0" radius="0.35" length="0.2"/>
    <visual>
      <geometry><cylinder radius="0.35" length="0.2"/></geometry>
      <material name="black"/>
    </visual>
    <collision>
      <geometry><cylinder radius="0.35" length="0.2"/></geometry>
    </collision>
  </link>
  

</robot>
